[2024-11-03T01:36:56.376+0000] {local_task_job_runner.py:120} INFO - ::group::Pre task execution logs
[2024-11-03T01:36:56.740+0000] {taskinstance.py:2076} INFO - Dependencies all met for dep_context=non-requeueable deps ti=<TaskInstance: songs_preprocessing.load_data_task manual__2024-11-03T01:36:51.503344+00:00 [queued]>
[2024-11-03T01:36:56.755+0000] {taskinstance.py:2076} INFO - Dependencies all met for dep_context=requeueable deps ti=<TaskInstance: songs_preprocessing.load_data_task manual__2024-11-03T01:36:51.503344+00:00 [queued]>
[2024-11-03T01:36:56.755+0000] {taskinstance.py:2306} INFO - Starting attempt 1 of 1
[2024-11-03T01:36:56.784+0000] {taskinstance.py:2330} INFO - Executing <Task(PythonOperator): load_data_task> on 2024-11-03 01:36:51.503344+00:00
[2024-11-03T01:36:56.801+0000] {warnings.py:112} WARNING - /home/***/.local/lib/python3.12/site-packages/***/task/task_runner/standard_task_runner.py:61: DeprecationWarning: This process (pid=660) is multi-threaded, use of fork() may lead to deadlocks in the child.
  pid = os.fork()

[2024-11-03T01:36:56.803+0000] {standard_task_runner.py:63} INFO - Started process 677 to run task
[2024-11-03T01:36:56.803+0000] {standard_task_runner.py:90} INFO - Running: ['***', 'tasks', 'run', 'songs_preprocessing', 'load_data_task', 'manual__2024-11-03T01:36:51.503344+00:00', '--job-id', '12', '--raw', '--subdir', 'DAGS_FOLDER/***.py', '--cfg-path', '/tmp/tmp1iw0gbj2']
[2024-11-03T01:36:56.807+0000] {standard_task_runner.py:91} INFO - Job 12: Subtask load_data_task
[2024-11-03T01:36:56.879+0000] {task_command.py:426} INFO - Running <TaskInstance: songs_preprocessing.load_data_task manual__2024-11-03T01:36:51.503344+00:00 [running]> on host 4a174f3124db
[2024-11-03T01:36:57.073+0000] {taskinstance.py:2648} INFO - Exporting env vars: AIRFLOW_CTX_DAG_OWNER='your_name' AIRFLOW_CTX_DAG_ID='songs_preprocessing' AIRFLOW_CTX_TASK_ID='load_data_task' AIRFLOW_CTX_EXECUTION_DATE='2024-11-03T01:36:51.503344+00:00' AIRFLOW_CTX_TRY_NUMBER='1' AIRFLOW_CTX_DAG_RUN_ID='manual__2024-11-03T01:36:51.503344+00:00'
[2024-11-03T01:36:57.075+0000] {taskinstance.py:430} INFO - ::endgroup::
[2024-11-03T01:37:01.343+0000] {taskinstance.py:441} INFO - ::group::Post task execution logs
[2024-11-03T01:37:01.344+0000] {taskinstance.py:2905} ERROR - Task failed with exception
Traceback (most recent call last):
  File "/home/airflow/.local/lib/python3.12/site-packages/airflow/models/taskinstance.py", line 465, in _execute_task
    result = _execute_callable(context=context, **execute_callable_kwargs)
             ^^^^^^^^^^^^^^^^^^^^^^^^^^^^^^^^^^^^^^^^^^^^^^^^^^^^^^^^^^^^^
  File "/home/airflow/.local/lib/python3.12/site-packages/airflow/models/taskinstance.py", line 432, in _execute_callable
    return execute_callable(context=context, **execute_callable_kwargs)
           ^^^^^^^^^^^^^^^^^^^^^^^^^^^^^^^^^^^^^^^^^^^^^^^^^^^^^^^^^^^^
  File "/home/airflow/.local/lib/python3.12/site-packages/airflow/models/baseoperator.py", line 401, in wrapper
    return func(self, *args, **kwargs)
           ^^^^^^^^^^^^^^^^^^^^^^^^^^^
  File "/home/airflow/.local/lib/python3.12/site-packages/airflow/operators/python.py", line 235, in execute
    return_value = self.execute_callable()
                   ^^^^^^^^^^^^^^^^^^^^^^^
  File "/home/airflow/.local/lib/python3.12/site-packages/airflow/operators/python.py", line 252, in execute_callable
    return self.python_callable(*self.op_args, **self.op_kwargs)
           ^^^^^^^^^^^^^^^^^^^^^^^^^^^^^^^^^^^^^^^^^^^^^^^^^^^^^
  File "/opt/airflow/dags/src/song_recommendation.py", line 21, in load_data
    with open(file_path, "wb") as file:
         ^^^^^^^^^^^^^^^^^^^^^
IsADirectoryError: [Errno 21] Is a directory: '../../data/'
[2024-11-03T01:37:01.367+0000] {taskinstance.py:1206} INFO - Marking task as FAILED. dag_id=songs_preprocessing, task_id=load_data_task, run_id=manual__2024-11-03T01:36:51.503344+00:00, execution_date=20241103T013651, start_date=20241103T013656, end_date=20241103T013701
[2024-11-03T01:37:01.382+0000] {standard_task_runner.py:110} ERROR - Failed to execute job 12 for task load_data_task ([Errno 21] Is a directory: '../../data/'; 677)
[2024-11-03T01:37:01.402+0000] {local_task_job_runner.py:240} INFO - Task exited with return code 1
[2024-11-03T01:37:01.427+0000] {taskinstance.py:3503} INFO - 0 downstream tasks scheduled from follow-on schedule check
[2024-11-03T01:37:01.441+0000] {local_task_job_runner.py:222} INFO - ::endgroup::
